2022-10-09 10:51:13,036 INFO    MainThread:1484654 [wandb_setup.py:_flush():76] Configure stats pid to 1484654
2022-10-09 10:51:13,038 INFO    MainThread:1484654 [wandb_setup.py:_flush():76] Loading settings from /home/see/.config/wandb/settings
2022-10-09 10:51:13,038 INFO    MainThread:1484654 [wandb_setup.py:_flush():76] Loading settings from /data/wyw/grid/ippo_qmix/wandb/settings
2022-10-09 10:51:13,039 INFO    MainThread:1484654 [wandb_setup.py:_flush():76] Loading settings from environment variables: {'_require_service': 'True'}
2022-10-09 10:51:13,040 INFO    MainThread:1484654 [wandb_setup.py:_flush():76] Inferring run settings from compute environment: {'program': '<python with no main file>'}
2022-10-09 10:51:13,042 INFO    MainThread:1484654 [wandb_init.py:_log_setup():461] Logging user logs to /data/wyw/grid/ippo_qmix/wandb/run-20221009_105112-20l2j2ss/logs/debug.log
2022-10-09 10:51:13,043 INFO    MainThread:1484654 [wandb_init.py:_log_setup():462] Logging internal logs to /data/wyw/grid/ippo_qmix/wandb/run-20221009_105112-20l2j2ss/logs/debug-internal.log
2022-10-09 10:51:13,043 INFO    MainThread:1484654 [wandb_init.py:init():495] calling init triggers
2022-10-09 10:51:13,044 INFO    MainThread:1484654 [wandb_init.py:init():498] wandb.init called with sweep_config: {}
config: {'model_name': '96agents', 'data_path': PosixPath('../envs/data/Climate_Zone_1'), 'climate_zone': 1, 'buildings_states_actions_file': '../envs/data/buildings_state_action_space.json', 'hourly_timesteps': 4, 'max_num_houses': None, 'houses_per_node': 3}
2022-10-09 10:51:13,044 INFO    MainThread:1484654 [wandb_init.py:init():514] re-initializing run, found existing run on stack: bpef38qa
2022-10-09 10:51:13,045 INFO    MainThread:1484654 [wandb_run.py:_finish():1728] finishing run wangyiwen/grid/bpef38qa
2022-10-09 10:51:13,161 INFO    MainThread:1484654 [jupyter.py:save_history():447] not saving jupyter history
2022-10-09 10:51:13,162 INFO    MainThread:1484654 [jupyter.py:save_ipynb():377] not saving jupyter notebook
2022-10-09 10:51:13,162 INFO    MainThread:1484654 [wandb_init.py:_jupyter_teardown():393] cleaning up jupyter logic
2022-10-09 10:51:13,163 INFO    MainThread:1484654 [wandb_run.py:_atexit_cleanup():1931] got exitcode: 0
2022-10-09 10:51:13,164 INFO    MainThread:1484654 [wandb_run.py:_restore():1914] restore
2022-10-09 10:51:13,165 INFO    MainThread:1484654 [wandb_run.py:_restore():1920] restore done
2022-10-09 10:51:13,177 INFO    MainThread:1484654 [wandb_run.py:_on_finish():2221] got exit ret: file_counts {
  wandb_count: 1
}
pusher_stats {
  uploaded_bytes: 681
  total_bytes: 681
}

2022-10-09 10:51:13,286 INFO    MainThread:1484654 [wandb_run.py:_on_finish():2221] got exit ret: file_counts {
  wandb_count: 1
}
pusher_stats {
  uploaded_bytes: 681
  total_bytes: 681
}

2022-10-09 10:51:13,768 INFO    MainThread:1484654 [wandb_run.py:_on_finish():2221] got exit ret: file_counts {
  wandb_count: 1
}
pusher_stats {
  uploaded_bytes: 681
  total_bytes: 681
}

2022-10-09 10:51:18,896 INFO    MainThread:1484654 [wandb_run.py:_restore():1914] restore
2022-10-09 10:51:18,896 INFO    MainThread:1484654 [wandb_run.py:_restore():1920] restore done
2022-10-09 10:51:19,900 ERROR   MainThread:1484654 [wandb_run.py:_atexit_cleanup():1952] Problem finishing run
Traceback (most recent call last):
  File "/home/see/anaconda3/envs/demand/lib/python3.8/site-packages/wandb/sdk/wandb_run.py", line 1940, in _atexit_cleanup
    self._on_finish()
  File "/home/see/anaconda3/envs/demand/lib/python3.8/site-packages/wandb/sdk/wandb_run.py", line 2219, in _on_finish
    self._backend.interface.communicate_poll_exit()
  File "/home/see/anaconda3/envs/demand/lib/python3.8/site-packages/wandb/sdk/interface/interface.py", line 673, in communicate_poll_exit
    resp = self._communicate_poll_exit(poll_exit)
  File "/home/see/anaconda3/envs/demand/lib/python3.8/site-packages/wandb/sdk/interface/interface_shared.py", line 424, in _communicate_poll_exit
    result = self._communicate(rec)
  File "/home/see/anaconda3/envs/demand/lib/python3.8/site-packages/wandb/sdk/interface/interface_shared.py", line 231, in _communicate
    return self._communicate_async(rec, local=local).get(timeout=timeout)
  File "/home/see/anaconda3/envs/demand/lib/python3.8/site-packages/wandb/sdk/interface/router.py", line 37, in get
    is_set = self._object_ready.wait(timeout)
  File "/home/see/anaconda3/envs/demand/lib/python3.8/threading.py", line 558, in wait
    signaled = self._cond.wait(timeout)
  File "/home/see/anaconda3/envs/demand/lib/python3.8/threading.py", line 306, in wait
    gotit = waiter.acquire(True, timeout)
  File "/home/see/anaconda3/envs/demand/lib/python3.8/pdb.py", line 194, in sigint_handler
    self.set_trace(frame)
  File "/home/see/anaconda3/envs/demand/lib/python3.8/site-packages/IPython/core/debugger.py", line 397, in set_trace
    def set_trace(self, frame=None):
  File "/home/see/anaconda3/envs/demand/lib/python3.8/bdb.py", line 90, in trace_dispatch
    return self.dispatch_call(frame, arg)
  File "/home/see/anaconda3/envs/demand/lib/python3.8/bdb.py", line 135, in dispatch_call
    if self.quitting: raise BdbQuit
bdb.BdbQuit
2022-10-09 10:51:19,904 INFO    MainThread:1484654 [wandb_init.py:init():548] starting backend
2022-10-09 10:51:19,904 INFO    MainThread:1484654 [wandb_init.py:init():552] setting up manager
2022-10-09 10:51:19,919 INFO    MainThread:1484654 [backend.py:_multiprocessing_setup():97] multiprocessing start_methods=fork,spawn,forkserver, using: spawn
2022-10-09 10:51:19,927 INFO    MainThread:1484654 [wandb_init.py:init():558] backend started and connected
2022-10-09 10:51:19,937 INFO    MainThread:1484654 [wandb_run.py:_label_probe_notebook():1105] probe notebook
2022-10-09 10:51:19,937 INFO    MainThread:1484654 [wandb_run.py:_label_probe_notebook():1115] Unable to probe notebook: 'NoneType' object has no attribute 'get'
2022-10-09 10:51:19,937 INFO    MainThread:1484654 [wandb_init.py:init():636] updated telemetry
2022-10-09 10:51:20,096 INFO    MainThread:1484654 [wandb_init.py:init():667] communicating run to backend with 30 second timeout
2022-10-09 10:51:21,919 INFO    MainThread:1484654 [wandb_run.py:_on_init():1982] communicating current version
2022-10-09 10:51:22,586 INFO    MainThread:1484654 [wandb_run.py:_on_init():1986] got version response upgrade_message: "wandb version 0.13.4 is available!  To upgrade, please run:\n $ pip install wandb --upgrade"

2022-10-09 10:51:22,586 INFO    MainThread:1484654 [wandb_init.py:init():700] starting run threads in backend
2022-10-09 10:51:22,640 WARNING MainThread:1484654 [wandb_init.py:init():1064] interrupted
Traceback (most recent call last):
  File "/home/see/anaconda3/envs/demand/lib/python3.8/site-packages/wandb/sdk/wandb_init.py", line 1043, in init
    run = wi.init()
  File "/home/see/anaconda3/envs/demand/lib/python3.8/site-packages/wandb/sdk/wandb_init.py", line 711, in init
    _ = backend.interface.communicate_run_start(run_obj)
  File "/home/see/anaconda3/envs/demand/lib/python3.8/site-packages/wandb/sdk/interface/interface.py", line 234, in communicate_run_start
    result = self._communicate_run_start(run_start)
  File "/home/see/anaconda3/envs/demand/lib/python3.8/site-packages/wandb/sdk/interface/interface_shared.py", line 445, in _communicate_run_start
    result = self._communicate(rec)
  File "/home/see/anaconda3/envs/demand/lib/python3.8/site-packages/wandb/sdk/interface/interface_shared.py", line 231, in _communicate
    return self._communicate_async(rec, local=local).get(timeout=timeout)
  File "/home/see/anaconda3/envs/demand/lib/python3.8/site-packages/wandb/sdk/interface/router.py", line 37, in get
    is_set = self._object_ready.wait(timeout)
  File "/home/see/anaconda3/envs/demand/lib/python3.8/threading.py", line 558, in wait
    signaled = self._cond.wait(timeout)
  File "/home/see/anaconda3/envs/demand/lib/python3.8/threading.py", line 306, in wait
    gotit = waiter.acquire(True, timeout)
KeyboardInterrupt
