Uncaught exception. Entering post mortem debugging
Running 'cont' or 'step' will restart the program
> /home/see/anaconda3/envs/demand/lib/python3.8/site-packages/torch/nn/modules/module.py(897)convert()
    896                             non_blocking, memory_format=convert_to_format)
--> 897             return t.to(device, dtype if t.is_floating_point() or t.is_complex() else None, non_blocking)
    898
Traceback (most recent call last):
  File "/home/see/anaconda3/envs/demand/lib/python3.8/site-packages/ipdb/__main__.py", line 305, in main
    pdb._runscript(mainpyfile)
  File "/home/see/anaconda3/envs/demand/lib/python3.8/pdb.py", line 1573, in _runscript
    self.run(statement)
  File "/home/see/anaconda3/envs/demand/lib/python3.8/bdb.py", line 580, in run
    exec(cmd, globals, locals)
  File "<string>", line 1, in <module>
  File "/data/wyw/grid/ippo_qmix/main.py", line 78, in <module>
    main()
  File "/data/wyw/grid/ippo_qmix/main.py", line 47, in main
    runner = RunnerSimpleSpreadEnv(env)
  File "/data/wyw/grid/ippo_qmix/runner.py", line 25, in __init__
    self.agents = MyAgents(self.env_info)
  File "/data/wyw/grid/ippo_qmix/agent/agents.py", line 54, in __init__
    self.policy = IndependentPPO(self.env_info)
  File "/data/wyw/grid/ippo_qmix/policy/independent_ppo.py", line 45, in __init__
    self.ppo_actor.to(self.device)
  File "/home/see/anaconda3/envs/demand/lib/python3.8/site-packages/torch/nn/modules/module.py", line 899, in to
    return self._apply(convert)
  File "/home/see/anaconda3/envs/demand/lib/python3.8/site-packages/torch/nn/modules/module.py", line 570, in _apply
    module._apply(fn)
  File "/home/see/anaconda3/envs/demand/lib/python3.8/site-packages/torch/nn/modules/module.py", line 593, in _apply
    param_applied = fn(param)
  File "/home/see/anaconda3/envs/demand/lib/python3.8/site-packages/torch/nn/modules/module.py", line 897, in convert
    return t.to(device, dtype if t.is_floating_point() or t.is_complex() else None, non_blocking)
RuntimeError: CUDA error: out of memory
CUDA kernel errors might be asynchronously reported at some other API call,so the stacktrace below might be incorrect.
For debugging consider passing CUDA_LAUNCH_BLOCKING=1.
Post mortem debugger finished. The main.py will be restarted
> /data/wyw/grid/ippo_qmix/main.py(1)<module>()
----> 1 import csv
      2 import os
      3